Workbook

Sheet Credit Summary
C2: Quanex credit underwriting summary
C4: Case selected: | D4: =Assumptions!$D$4 -> Base
C5: Phase 8 model — final credit recommendation pending Phase 10
C7: Transaction and opening position | H7: Warnings, protections and unresolved conditions
C8: Borrower | D8: Quanex Building Products Corporation | H8: Status | I8: Date / value | J8: Interpretation
C9: Information cutoff | D9: 46006 | H9: First warning | I9: ='Scenario Comparison'!S5 -> N/D | J9: Analyst warning; does not terminate draws
C10: Hypothetical closing | D10: 46053 | H10: First covenant breach | I10: ='Scenario Comparison'!T5 -> N/D | J10: Proposed maintenance test
C11: Selected structure | D11: $635m term / $300m revolver / $15m conditional source | H11: First draw shutoff | I11: ='Scenario Comparison'!U5 -> N/D | J11: Path-specific no-waiver convention
C12: Bank hold cap | D12: 50 | H12: First mandatory-payment failure | I12: ='Scenario Comparison'!V5 -> N/D | J12: Separate from covenant and liquidity status
C13: Opening total funded debt | D13: =Transaction!D17 -> 727.51672 | H13: Maturity gap | I13: ='Scenario Comparison'!X5 -> 324.77971 | J13: No maturity refinancing assumed
C14: Opening gross leverage | D14: =Transaction!D18 -> 3.2284717
C16: Selected-case outcomes | H16: Type | I16: Item | J16: Status
C17: FY2026 post-closing lender-base EBITDA | D17: ='Scenario Comparison'!F5 -> 190.24864 | H17: Risk | I17: Tyman integration / $302.284m impairment | J17: Major adverse forecasting signal
C18: Modeled operating cash | D18: ='Scenario Comparison'!H5 -> 794.48407 | H18: Risk | I18: Adjustment-heavy earnings / cash conversion | J18: Monitor
C19: CFADS through maturity | D19: ='Scenario Comparison'!I5 -> 640.30851 | H19: Protection | I19: 3.50x / 3.25x / 3.00x gross leverage covenant | J19: Proposed
C20: Cash interest | D20: ='Scenario Comparison'!J5 -> 167.38575 | H20: Protection | I20: 50% ECF sweep / distribution restrictions | J20: Proposed
C21: Opening usable liquidity | D21: ='Scenario Comparison'!N5 -> 263.90228 | H21: Condition | I21: $15m source / separate $25m cash floor | J21: Pending information
C22: Subsequent minimum liquidity | D22: ='Scenario Comparison'!O5 -> 270.34135 | H22: Condition | I22: Closing LTM interest / official compliance | J22: N/D
C23: All-in minimum liquidity | D23: ='Scenario Comparison'!P5 -> 263.90228 | H23: Condition | I23: Debt / EBITDA / ECF / cure / draw definitions | J23: Pending legal diligence
C24: Maximum gross leverage | D24: ='Scenario Comparison'!Q5 -> 3.2284717 | H24: Alternative | I24: Retain or amend existing facilities | J24: Live alternative; amendment economics N/D
C25: Minimum cash-interest coverage | D25: ='Scenario Comparison'!R5 -> 5.3859581
C26: Closing cash-interest coverage | D26: N/D
C27: Common-horizon ending funded debt | D27: ='Scenario Comparison'!W5 -> 514.75371
C28: Unsupported maturity gap | D28: ='Scenario Comparison'!X5 -> 324.77971

Sheet Assumptions
C2: Quanex underwriting assumptions
C4: Case selected: | D4: Base
C5: Scenario ID | D5: =INDEX($BE$41:$BE$49,MATCH($D$4,$BD$41:$BD$49,0)) -> BASE
C6: Approved input version | D6: 58e1b83a644021b785162d851e1539dd65dff9f5
C7: Current input signature | D7: =ROUND(SUMPRODUCT($D$12:$D$35,ROW($D$12:$D$35))+SUMPRODUCT($L$41:$L$364,ROW($L$41:$L$364))/1000+SUMPRODUCT($N$41:$N$364,ROW($N$41:$N$364))/10000,6) -> 1712129.8
C8: Source-file hash | D8: 126ef393472d5f74abd447b237b1319643c1effb36a37f052496b114af1a6fe1
C10: Financing, covenant and sensitivity controls | H10: Policy, status and unresolved-definition register
C11: Control | D11: Value | E11: Units | F11: Source / assumption ID | G11: Status / limitation | H11: Area | I11: Approved rule / unresolved item | J11: Status | K11: Source | L11: Workbook treatment
C12: Term commitment | D12: 635 | E12: USD millions | F12: P7FA-002 | G12: Owner-reviewed provisional | H12: Repurchases | I12: No directly debt-funded repurchases; none while revolver is outstanding | J12: Owner reviewed | K12: P7FA-030 | L12: No unapproved cash-flow benefit
C13: Conditional non-debt contribution | D13: 15 | E13: USD millions | F13: P7FA-007 | G13: Pending evidence; separate from cash floor | H13: Dividends | I13: Require no default, gross leverage <=3.00x and usable liquidity >=$75m after payment | J13: Owner reviewed | K13: P7FA-030 | L13: Approved Phase 7 scenario cash flows retained
C14: Revolver commitment | D14: 300 | E14: USD millions | F14: P7FA-009 | G14: Owner-reviewed provisional | H14: Warning | I14: Suspends repurchases and triggers enhanced reporting | J14: Owner reviewed | K14: P7FA-027/P7FA-028 | L14: Warning alone does not terminate draws
C15: Opening revolver | D15: =679.89771875-D12-D13 -> 29.897719 | E15: USD millions | F15: Formula | G15: Reference uses less term and contribution | H15: Covenant breach | I15: Suspends all restricted payments | J15: Owner reviewed | K15: P7FA-030 | L15: Reported separately from warning
C16: Letters of credit | D16: 6.2 | E16: USD millions | F16: P7FA-010 | G16: Inherited reference | H16: Drawability | I16: Analytical shutoff, covenant-linked no-waiver and continued-draw paths remain distinct | J16: Owner reviewed | K16: P7FA-031 | L16: Selector preserves all approved paths
C17: Retained other funded debt | D17: 62.619 | E17: USD millions | F17: P7FA-013 | G17: Conservative proxy | H17: Covenant cash | I17: Eligible covenant cash | J17: N/D | K17: P7FA-012 | L17: Zero cash netting in proposed leverage tests
C18: Annual term amortization | D18: 0.075 | E18: percent | F18: P7FA-016 | G18: Paid quarterly | H18: Book-cash leverage | I18: Book cash may not equal accessible covenant cash | J18: Diagnostic only | K18: P7FA-012 | L18: Not covenant or lender net leverage
C19: Modeled all-in interest rate | D19: 0.0657 | E19: percent | F19: P7FA-020 | G19: Testing assumption | H19: Conditional source | I19: $15m non-debt contribution availability and accessibility | J19: Condition precedent | K19: P7FA-007 | L19: Displayed separately; not verified cash
C20: Incremental interest spread | D20: 0 | E20: percent | F20: Phase 8 control | G20: Sensitivity overlay | H20: Closing coverage | I20: Complete closing LTM cash interest | J20: N/D | K20: P7FA-019 | L20: Closing coverage remains N/D
C21: EBITDA overlay | D21: 0 | E21: percent | F21: Phase 8 control | G21: Sensitivity overlay; zero in approved case | H21: Legal definitions | I21: Debt, EBITDA, ECF, cure, draw, default and waiver definitions | J21: Pending information | K21: P7FA-026 | L21: Not presented as official compliance
C22: Base DSO | D22: 41.5 | E22: days | F22: P5A-004 | G22: Approved testing input
C23: DSO change | D23: 0 | E23: days | F23: Phase 8 control | G23: Sensitivity overlay
C24: Operating cash floor | D24: 25 | E24: USD millions | F24: P7FA-021 | G24: Separate operating control
C25: Liquidity overlay per period | D25: 0 | E25: USD millions | F25: Phase 8 control | G25: Sensitivity overlay
C26: ECF sweep | D26: 0.5 | E26: percent | F26: P7FA-029 | G26: After revolver repayment and safeguards
C27: Initial leverage covenant | D27: 3.5 | E27: turns | F27: P7FA-022 | G27: Through 10/31/27
C28: Step 1 leverage covenant | D28: 3.25 | E28: turns | F28: P7FA-023 | G28: Through 10/31/28
C29: Step 2 leverage covenant | D29: 3 | E29: turns | F29: P7FA-024 | G29: Thereafter
C30: Interest coverage covenant | D30: 3 | E30: turns | F30: P7FA-025 | G30: Minimum
C31: Liquidity covenant | D31: 50 | E31: USD millions | F31: P7FA-026 | G31: Minimum usable liquidity
C32: Initial leverage warning | D32: 3.25 | E32: turns | F32: P7FA-027 | G32: Inclusive warning
C33: Coverage warning | D33: 3.5 | E33: turns | F33: P7FA-028 | G33: Minimum analyst warning
... C35: Maturity | D35: 47879 | E35: date | F35: P7FA-017 | G35: No refinancing assumed
C40: scenario name | D40: scenario id | E40: model period id | F40: frequency | G40: period start | H40: period end | I40: fiscal year | J40: quarter | K40: days in period | L40: revenue | M40: base gross margin percent | N40: lender base ebitda | O40: depreciation and amortization | P40: cash tax proxy | Q40: working capital cash flow | R40: capital expenditures | S40: other operating cash uses | T40: cfads before cash interest | U40: opening cash | V40: ending cash | W40: opening term principal | X40: scheduled term principal due | Y40: scheduled term principal paid | Z40: cash sweep | AA40: maturity principal due | AB40: maturity principal paid | AC40: ending term principal | AD40: opening revolver | AE40: revolver draw | AF40: revolver repayment | AG40: ending revolver | AH40: cash interest due | AI40: cash interest paid | AJ40: retained obligation paid | AK40: dividend paid | AL40: repurchase paid | AM40: failed obligation unpaid amount | AN40: gross funded debt | AO40: minimum usable liquidity | AP40: peak revolver | AQ40: nominal revolver availability | AR40: drawability status | AS40: drawability shutoff date | AT40: ttm lender base ebitda | AU40: gross funded leverage | AV40: ebitda cash interest coverage | AW40: unsupported maturity gap | AX40: maturity event | AY40: mandatory payment failure flag | AZ40: model status | BA40: source ids | BB40: upstream ids | BD40: scenario name | BE40: scenario id | BF40: first warning | BG40: first breach | BH40: first shutoff | BI40: first payment failure | BJ40: common ending debt | BK40: maturity gap | BL40: opening liquidity | BM40: subsequent minimum | BN40: all in minimum | BO40: maximum leverage | BP40: minimum coverage
C41: Base | D41: BASE | E41: P001 | F41: monthly | G41: 46054 | H41: 46081 | I41: FY2026 | J41: Q2 | K41: 28 | L41: 150.82223 | M41: 28.869322 | N41: 21.062659 | O41: -8.4900849 | P41: -3.1431434 | Q41: -0.024735049 | R41: -5.278778 | S41: -0.23333333 | T41: 12.382669 | U41: 25 | V41: 25 | W41: 635 | X41: 0 | Y41: 0 | Z41: 0 | AA41: 0 | AB41: 0 | AC41: 635 | AD41: 29.897719 | AE41: 0 | AF41: 6.4390641 | AG41: 23.458655 | AH41: 3.6226881 | AI41: 3.6226881 | AJ41: 0.69591667 | AK41: 1.2083333 | AL41: 0.41666667 | AM41: 0 | AN41: 721.07765 | AO41: 270.34135 | AP41: 23.458655 | AQ41: 270.34135 | AR41: available_before_analytical_shutoff | AW41: 0 | AX41: no | AY41: no | AZ41: PASS | BA41: SRC-001;SRC-002;SRC-003 | BB41: P6M-BASE-P-0001:P6M-BASE-P-0001 | BD41: Base | BE41: BASE | BF41: N/D | BG41: N/D | BH41: N/D | BI41: N/D | BJ41: 514.75371 | BK41: 324.77971 | BL41: 263.90228 | BM41: 270.34135 | BN41: 263.90228 | BO41: 3.2284717 | BP41: 5.3859581
C42: Base | D42: BASE | E42: P002 | F42: monthly | G42: 46082 | H42: 46112 | I42: FY2026 | J42: Q2 | K42: 31 | L42: 150.82223 | M42: 28.869322 | N42: 21.062659 | O42: -8.4900849 | P42: -3.1431434 | Q42: -0.024735049 | R42: -5.278778 | S42: -0.23333333 | T42: 12.382669 | U42: 25 | V42: 25 | W42: 635 | X42: 0 | Y42: 0 | Z42: 0 | AA42: 0 | AB42: 0 | AC42: 635 | AD42: 23.458655 | AE42: 0 | AF42: 6.4744148 | AG42: 16.98424 | AH42: 3.5873374 | AI42: 3.5873374 | AJ42: 0.69591667 | AK42: 1.2083333 | AL42: 0.41666667 | AM42: 0 | AN42: 714.60324 | AO42: 276.81576 | AP42: 16.98424 | AQ42: 276.81576 | AR42: available_before_analytical_shutoff | AW42: 0 | AX42: no | AY42: no | AZ42: PASS | BA42: SRC-001;SRC-002;SRC-003 | BB42: P6M-BASE-P-0002:P6M-BASE-P-0002 | BD42: Moderate unmitigated | BE42: MODERATE_UNMITIGATED | BF42: 2026-10-31 | BG42: 2026-10-31 | BH42: N/D | BI42: N/D | BL42: 263.90228 | BM42: 165.07841 | BN42: 165.07841 | BO42: 4.4892502 | BP42: 3.2103738
C43: Base | D43: BASE | E43: P003 | F43: monthly | G43: 46113 | H43: 46142 | I43: FY2026 | J43: Q2 | K43: 30 | L43: 150.82223 | M43: 28.869322 | N43: 21.062659 | O43: -8.4900849 | P43: -3.1431434 | Q43: -0.024735049 | R43: -5.278778 | S43: -0.23333333 | T43: 12.382669 | U43: 25 | V43: 25 | W43: 635 | X43: 11.90625 | Y43: 11.90625 | Z43: 0 | AA43: 0 | AB43: 0 | AC43: 623.09375 | AD43: 16.98424 | AE43: 5.3962905 | AF43: 0 | AG43: 22.38053 | AH43: 3.5517927 | AI43: 3.5517927 | AJ43: 0.69591667 | AK43: 1.2083333 | AL43: 0.41666667 | AM43: 0 | AN43: 708.09328 | AO43: 271.41947 | AP43: 22.38053 | AQ43: 271.41947 | AR43: available_before_analytical_shutoff | AW43: 0 | AX43: no | AY43: no | AZ43: PASS | BA43: SRC-001;SRC-002;SRC-003 | BB43: P6M-BASE-P-0003:P6M-BASE-P-0003 | BD43: Moderate mitigated | BE43: MODERATE_MITIGATED | BF43: 2026-10-31 | BG43: 2026-10-31 | BH43: N/D | BI43: N/D | BL43: 263.90228 | BM43: 168.93692 | BN43: 168.93692 | BO43: 4.4670061 | BP43: 3.2168341
C44: Base | D44: BASE | E44: P004 | F44: monthly | G44: 46143 | H44: 46173 | I44: FY2026 | J44: Q3 | K44: 31 | L44: 165.08687 | M44: 27.690174 | N44: 21.108129 | O44: -9.2930702 | P44: -2.9537647 | Q44: -0.027069577 | R44: -5.7780405 | S44: 0 | T44: 12.349254 | U44: 25 | V44: 25 | W44: 623.09375 | X44: 0 | Y44: 0 | Z44: 0 | AA44: 0 | AB44: 0 | AC44: 623.09375 | AD44: 22.38053 | AE44: 0 | AF44: 6.512193 | AG44: 15.868337 | AH44: 3.5161446 | AI44: 3.5161446 | AJ44: 0.69591667 | AK44: 1.2083333 | AL44: 0.41666667 | AM44: 0 | AN44: 701.58109 | AO44: 277.93166 | AP44: 15.868337 | AQ44: 277.93166 | AR44: available_before_analytical_shutoff | AW44: 0 | AX44: no | AY44: no | AZ44: PASS | BA44: SRC-001;SRC-002;SRC-003 | BB44: P6M-BASE-P-0004:P6M-BASE-P-0004 | BD44: Severe unmitigated | BE44: SEVERE_UNMITIGATED | BF44: 2026-04-30 | BG44: 2026-10-31 | BH44: N/D | BI44: 2027-12-31 | BL44: 263.90228 | BM44: 0 | BN44: 0 | BO44: 7.0574015 | BP44: 1.7819351
C45: Base | D45: BASE | E45: P005 | F45: monthly | G45: 46174 | H45: 46203 | I45: FY2026 | J45: Q3 | K45: 30 | L45: 165.08687 | M45: 27.690174 | N45: 21.108129 | O45: -9.2930702 | P45: -2.9537647 | Q45: -0.027069577 | R45: -5.7780405 | S45: 0 | T45: 12.349254 | U45: 25 | V45: 25 | W45: 623.09375 | X45: 0 | Y45: 0 | Z45: 0 | AA45: 0 | AB45: 0 | AC45: 623.09375 | AD45: 15.868337 | AE45: 0 | AF45: 6.5479451 | AG45: 9.3203922 | AH45: 3.4803924 | AI45: 3.4803924 | AJ45: 0.69591667 | AK45: 1.2083333 | AL45: 0.41666667 | AM45: 0 | AN45: 695.03314 | AO45: 284.47961 | AP45: 9.3203922 | AQ45: 284.47961 | AR45: available_before_analytical_shutoff | AW45: 0 | AX45: no | AY45: no | AZ45: PASS | BA45: SRC-001;SRC-002;SRC-003 | BB45: P6M-BASE-P-0005:P6M-BASE-P-0005 | BD45: Severe mitigated | BE45: SEVERE_MITIGATED | BF45: 2026-04-30 | BG45: 2026-10-31 | BH45: N/D | BI45: 2028-01-31 | BL45: 263.90228 | BM45: 0 | BN45: 0 | BO45: 6.9528556 | BP45: 1.800808
C46: Base | D46: BASE | E46: P006 | F46: monthly | G46: 46204 | H46: 46234 | I46: FY2026 | J46: Q3 | K46: 31 | L46: 165.08687 | M46: 27.690174 | N46: 21.108129 | O46: -9.2930702 | P46: -2.9537647 | Q46: -0.027069577 | R46: -5.7780405 | S46: 0 | T46: 12.349254 | U46: 25 | V46: 25 | W46: 623.09375 | X46: 11.90625 | Y46: 11.90625 | Z46: 0 | AA46: 0 | AB46: 0 | AC46: 611.1875 | AD46: 9.3203922 | AE46: 5.3223565 | AF46: 0 | AG46: 14.642749 | AH46: 3.444444 | AI46: 3.444444 | AJ46: 0.69591667 | AK46: 1.2083333 | AL46: 0.41666667 | AM46: 0 | AN46: 688.44925 | AO46: 279.15725 | AP46: 14.642749 | AQ46: 279.15725 | AR46: available_before_analytical_shutoff | AW46: 0 | AX46: no | AY46: no | AZ46: PASS | BA46: SRC-001;SRC-002;SRC-003 | BB46: P6M-BASE-P-0006:P6M-BASE-P-0006 | BD46: Moderate Phase 6 analytical shutoff | BE46: MODERATE_NO_WAIVER | BF46: 2026-10-31 | BG46: 2026-10-31 | BH46: 2026-11-30 | BI46: N/D | BL46: 263.90228 | BM46: 0 | BN46: 0 | BO46: 4.3787434 | BP46: 3.2181715
C47: Base | D47: BASE | E47: P007 | F47: monthly | G47: 46235 | H47: 46265 | I47: FY2026 | J47: Q4 | K47: 31 | L47: 163.27792 | M47: 27.915917 | N47: 21.245425 | O47: -9.1912406 | P47: -3.013546 | Q47: -0.026773886 | R47: -5.7147271 | S47: 0 | T47: 12.490378 | U47: 25 | V47: 25 | W47: 611.1875 | X47: 0 | Y47: 0 | Z47: 0 | AA47: 0 | AB47: 0 | AC47: 611.1875 | AD47: 14.642749 | AE47: 0 | AF47: 6.76155 | AG47: 7.8811987 | AH47: 3.4079109 | AI47: 3.4079109 | AJ47: 0.69591667 | AK47: 1.2083333 | AL47: 0.41666667 | AM47: 0 | AN47: 681.6877 | AO47: 285.9188 | AP47: 7.8811987 | AQ47: 285.9188 | AR47: available_before_analytical_shutoff | AW47: 0 | AX47: no | AY47: no | AZ47: PASS | BA47: SRC-001;SRC-002;SRC-003 | BB47: P6M-BASE-P-0007:P6M-BASE-P-0007 | BD47: Severe Phase 6 analytical shutoff | BE47: SEVERE_NO_WAIVER | BF47: 2026-04-30 | BG47: 2026-10-31 | BH47: 2026-11-30 | BI47: 2027-02-28 | BL47: 263.90228 | BM47: 0 | BN47: 0 | BO47: 6.8131589 | BP47: 1.861981
C48: Base | D48: BASE | E48: P008 | F48: monthly | G48: 46266 | H48: 46295 | I48: FY2026 | J48: Q4 | K48: 30 | L48: 163.27792 | M48: 27.915917 | N48: 21.245425 | O48: -9.1912406 | P48: -3.013546 | Q48: -0.026773886 | R48: -5.7147271 | S48: 0 | T48: 12.490378 | U48: 25 | V48: 25 | W48: 611.1875 | X48: 0 | Y48: 0 | Z48: 0 | AA48: 0 | AB48: 0 | AC48: 611.1875 | AD48: 7.8811987 | AE48: 0 | AF48: 6.7986711 | AG48: 1.0825276 | AH48: 3.3707898 | AI48: 3.3707898 | AJ48: 0.69591667 | AK48: 1.2083333 | AL48: 0.41666667 | AM48: 0 | AN48: 674.88903 | AO48: 292.71747 | AP48: 1.0825276 | AQ48: 292.71747 | AR48: available_before_analytical_shutoff | AW48: 0 | AX48: no | AY48: no | AZ48: PASS | BA48: SRC-001;SRC-002;SRC-003 | BB48: P6M-BASE-P-0008:P6M-BASE-P-0008 | BD48: Moderate Phase 7 covenant-linked no-waiver | BE48: MODERATE_PHASE7_COVENANT_NO_WAIVER | BF48: 2026-10-31 | BG48: 2026-10-31 | BH48: 2026-11-30 | BI48: N/D | BL48: 263.90228 | BM48: 0 | BN48: 0 | BO48: 4.3787434 | BP48: 3.2181715
...

Sheet Scenario Comparison
C2: Live scenario and captured comparisons
C3: Case selected: | D3: =Assumptions!$D$4 -> Base
C4: View | D4: Scenario ID | E4: Status | F4: FY2026 post-close EBITDA | G4: EBITDA margin | H4: Modeled operating cash | I4: CFADS | J4: Cash interest | K4: Scheduled principal | L4: ECF sweep | M4: Peak revolver | N4: Opening liquidity | O4: Subsequent minimum | P4: All-in minimum | Q4: Maximum leverage | R4: Minimum coverage | S4: First warning | T4: First breach | U4: First draw shutoff | V4: First payment failure | W4: Common-horizon ending debt | X4: Maturity gap | Y4: Unpaid obligations
C5: ="LIVE" -> LIVE | D5: =Assumptions!D5 -> BASE | E5: ="Current selection" -> Current selection | F5: =SUM(Forecast!D14:F14) -> 190.24864 | G5: =SUM(Forecast!D14:F14)/SUM(Forecast!D10:F10) -> 0.13234126 | H5: =SUM(Forecast!D24:W24) -> 794.48407 | I5: =SUM(Forecast!D22:W22) -> 640.30851 | J5: =SUM('Debt Schedule'!T12:T47) -> 167.38575 | K5: =SUM('Debt Schedule'!K12:K47) -> 238.125 | L5: =SUM('Debt Schedule'!L12:L47) -> 57.292168 | M5: =MAX('Debt Schedule'!R12:R47) -> 23.458655 | N5: =Liquidity!D6 -> 263.90228 | O5: =Liquidity!D7 -> 270.34135 | P5: =Liquidity!D9 -> 263.90228 | Q5: =MAX(Covenants!H8:H27) -> 3.2284717 | R5: =MIN(Covenants!N8:N27) -> 5.3859581 | S5: =INDEX(Assumptions!$BF$41:$BF$49,MATCH(Assumptions!$D$4,Assumptions!$BD$41:$BD$49,0)) -> N/D | T5: =INDEX(Assumptions!$BG$41:$BG$49,MATCH(Assumptions!$D$4,Assumptions!$BD$41:$BD$49,0)) -> N/D | U5: =INDEX(Assumptions!$BH$41:$BH$49,MATCH(Assumptions!$D$4,Assumptions!$BD$41:$BD$49,0)) -> N/D | V5: =INDEX(Assumptions!$BI$41:$BI$49,MATCH(Assumptions!$D$4,Assumptions!$BD$41:$BD$49,0)) -> N/D | W5: =SUMIFS('Debt Schedule'!Z12:Z47,'Debt Schedule'!D12:D47,DATE(2029,7,31)) -> 514.75371 | X5: ='Debt Schedule'!X47 -> 324.77971 | Y5: =SUM('Debt Schedule'!AC12:AC47) -> 0
C6: Current selected-case results
C8: Captured comparisons are recalculated snapshots, not parallel live engines. Change in any modeled input makes the stale flag visible until the capture workflow is rerun.
C11: Scenario | D11: Scenario ID | E11: View | F11: FY2026 post-close EBITDA | G11: EBITDA margin | H11: Modeled operating cash | I11: CFADS | J11: Cash interest | K11: Scheduled principal | L11: ECF sweep | M11: Peak revolver | N11: Opening liquidity | O11: Subsequent minimum | P11: All-in minimum | Q11: Maximum leverage | R11: Minimum coverage | S11: First warning | T11: First breach | U11: First draw shutoff | V11: First payment failure | W11: Common-horizon ending debt | X11: Maturity gap | Y11: Unpaid obligations | Z11: Captured at | AA11: Input version | AB11: Source hash | AC11: Captured signature | AD11: Current signature | AE11: Stale status
C12: Base | D12: BASE | E12: =IF(C12=Assumptions!$D$4,"LIVE SELECTED","CAPTURED") -> LIVE SELECTED | F12: 190.24864 | G12: 0.13234126 | H12: 794.48407 | I12: 640.30851 | J12: 167.38575 | K12: 238.125 | L12: 57.292168 | M12: 23.458655 | N12: 263.90228 | O12: 270.34135 | P12: 263.90228 | Q12: 3.2284717 | R12: 5.3859581 | S12: N/D | T12: N/D | U12: N/D | V12: N/D | W12: 514.75371 | X12: 324.77971 | Y12: 0 | Z12: 2026-09-11T17:39:57Z | AA12: 58e1b83a644021b785162d851e1539dd65dff9f5 | AB12: 126ef393472d5f74abd447b237b1319643c1effb36a37f052496b114af1a6fe1 | AC12: 1712129.8 | AD12: =Assumptions!$D$7 -> 1712129.8 | AE12: =IF(ABS(AC12-AD12)<=0.000001,"CURRENT","STALE") -> CURRENT
C13: Moderate unmitigated | D13: MODERATE_UNMITIGATED | E13: =IF(C13=Assumptions!$D$4,"LIVE SELECTED","CAPTURED") -> CAPTURED | F13: 151.00008 | G13: 0.11234126 | H13: 705.09412 | I13: 589.29204 | J13: 199.96478 | K13: 238.125 | L13: 0 | M13: 128.72159 | N13: 263.90228 | O13: 165.07841 | P13: 165.07841 | Q13: 4.4892502 | R13: 3.2103738 | S13: 2026-10-31 | T13: 2026-10-31 | U13: N/D | V13: N/D | W13: 569.06713 | X13: 408.37522 | Y13: 0 | Z13: 2026-09-11T17:39:57Z | AA13: 58e1b83a644021b785162d851e1539dd65dff9f5 | AB13: 126ef393472d5f74abd447b237b1319643c1effb36a37f052496b114af1a6fe1 | AC13: 1712129.8 | AD13: =Assumptions!$D$7 -> 1712129.8 | AE13: =IF(ABS(AC13-AD13)<=0.000001,"CURRENT","STALE") -> CURRENT
C14: Moderate mitigated | D14: MODERATE_MITIGATED | E14: =IF(C14=Assumptions!$D$4,"LIVE SELECTED","CAPTURED") -> CAPTURED | F14: 151.00008 | G14: 0.11234126 | H14: 708.58676 | I14: 589.29204 | J14: 196.47214 | K14: 238.125 | L14: 11.825378 | M14: 124.86308 | N14: 263.90228 | O14: 168.93692 | P14: 168.93692 | Q14: 4.4670061 | R14: 3.2168341 | S14: 2026-10-31 | T14: 2026-10-31 | U14: N/D | V14: N/D | W14: 550.9112 | X14: 381.13258 | Y14: 0 | Z14: 2026-09-11T17:39:57Z | AA14: 58e1b83a644021b785162d851e1539dd65dff9f5 | AB14: 126ef393472d5f74abd447b237b1319643c1effb36a37f052496b114af1a6fe1 | AC14: 1712129.8 | AD14: =Assumptions!$D$7 -> 1712129.8 | AE14: =IF(ABS(AC14-AD14)<=0.000001,"CURRENT","STALE") -> CURRENT
C15: Severe unmitigated | D15: SEVERE_UNMITIGATED | E15: =IF(C15=Assumptions!$D$4,"LIVE SELECTED","CAPTURED") -> CAPTURED | F15: 115.88908 | G15: 0.094841257 | H15: 483.56215 | I15: 467.10058 | J15: 280.89648 | K15: 226.21875 | L15: 0 | M15: 293.8 | N15: 263.90228 | O15: 0 | P15: 0 | Q15: 7.0574015 | R15: 1.7819351 | S15: 2026-04-30 | T15: 2026-10-31 | U15: N/D | V15: 2027-12-31 | W15: 741.46447 | X15: 604.25801 | Y15: 9.8304704 | Z15: 2026-09-11T17:39:57Z | AA15: 58e1b83a644021b785162d851e1539dd65dff9f5 | AB15: 126ef393472d5f74abd447b237b1319643c1effb36a37f052496b114af1a6fe1 | AC15: 1712129.8 | AD15: =Assumptions!$D$7 -> 1712129.8 | AE15: =IF(ABS(AC15-AD15)<=0.000001,"CURRENT","STALE") -> CURRENT
C16: Severe mitigated | D16: SEVERE_MITIGATED | E16: =IF(C16=Assumptions!$D$4,"LIVE SELECTED","CAPTURED") -> CAPTURED | F16: 115.88908 | G16: 0.094841257 | H16: 480.37732 | I16: 467.10058 | J16: 284.0813 | K16: 234.53779 | L16: 0 | M16: 293.8 | N16: 263.90228 | O16: 0 | P16: 0 | Q16: 6.9528556 | R16: 1.800808 | S16: 2026-04-30 | T16: 2026-10-31 | U16: N/D | V16: 2028-01-31 | W16: 714.07259 | X16: 554.71819 | Y16: 3.6418421 | Z16: 2026-09-11T17:39:57Z | AA16: 58e1b83a644021b785162d851e1539dd65dff9f5 | AB16: 126ef393472d5f74abd447b237b1319643c1effb36a37f052496b114af1a6fe1 | AC16: 1712129.8 | AD16: =Assumptions!$D$7 -> 1712129.8 | AE16: =IF(ABS(AC16-AD16)<=0.000001,"CURRENT","STALE") -> CURRENT
C17: Moderate Phase 6 analytical shutoff | D17: MODERATE_NO_WAIVER | E17: =IF(C17=Assumptions!$D$4,"LIVE SELECTED","CAPTURED") -> CAPTURED | F17: 151.00008 | G17: 0.11234126 | H17: 706.25135 | I17: 589.29204 | J17: 198.80756 | K17: 238.125 | L17: 0 | M17: 110.3219 | N17: 263.90228 | O17: 183.4781 | P17: 183.4781 | Q17: 4.3787434 | R17: 3.2181715 | S17: 2026-10-31 | T17: 2026-10-31 | U17: 2026-11-30 | V17: N/D | W17: 563.79487 | X17: 396.875 | Y17: 0 | Z17: 2026-09-11T17:39:57Z | AA17: 58e1b83a644021b785162d851e1539dd65dff9f5 | AB17: 126ef393472d5f74abd447b237b1319643c1effb36a37f052496b114af1a6fe1 | AC17: 1712129.8 | AD17: =Assumptions!$D$7 -> 1712129.8 | AE17: =IF(ABS(AC17-AD17)<=0.000001,"CURRENT","STALE") -> CURRENT
C18: Severe Phase 6 analytical shutoff | D18: SEVERE_NO_WAIVER | E18: =IF(C18=Assumptions!$D$4,"LIVE SELECTED","CAPTURED") -> CAPTURED | F18: 115.88908 | G18: 0.094841257 | H18: 513.52483 | I18: 467.10058 | J18: 250.9338 | K18: 210.96251 | L18: 0 | M18: 239.69285 | N18: 263.90228 | O18: 54.107146 | P18: 54.107146 | Q18: 6.8131589 | R18: 1.861981 | S18: 2026-04-30 | T18: 2026-10-31 | U18: 2026-11-30 | V18: 2027-02-28 | W18: 689.71319 | X18: 538.04051 | Y18: 41.947002 | Z18: 2026-09-11T17:39:57Z | AA18: 58e1b83a644021b785162d851e1539dd65dff9f5 | AB18: 126ef393472d5f74abd447b237b1319643c1effb36a37f052496b114af1a6fe1 | AC18: 1712129.8 | AD18: =Assumptions!$D$7 -> 1712129.8 | AE18: =IF(ABS(AC18-AD18)<=0.000001,"CURRENT","STALE") -> CURRENT
C19: Moderate Phase 7 covenant-linked no-waiver | D19: MODERATE_PHASE7_COVENANT_NO_WAIVER | E19: =IF(C19=Assumptions!$D$4,"LIVE SELECTED","CAPTURED") -> CAPTURED | F19: 151.00008 | G19: 0.11234126 | H19: 706.25135 | I19: 589.29204 | J19: 198.80756 | K19: 238.125 | L19: 0 | M19: 110.3219 | N19: 263.90228 | O19: 183.4781 | P19: 183.4781 | Q19: 4.3787434 | R19: 3.2181715 | S19: 2026-10-31 | T19: 2026-10-31 | U19: 2026-11-30 | V19: N/D | W19: 563.79487 | X19: 396.875 | Y19: 0 | Z19: 2026-09-11T17:39:57Z | AA19: 58e1b83a644021b785162d851e1539dd65dff9f5 | AB19: 126ef393472d5f74abd447b237b1319643c1effb36a37f052496b114af1a6fe1 | AC19: 1712129.8 | AD19: =Assumptions!$D$7 -> 1712129.8 | AE19: =IF(ABS(AC19-AD19)<=0.000001,"CURRENT","STALE") -> CURRENT
C20: Severe Phase 7 covenant-linked no-waiver | D20: SEVERE_PHASE7_COVENANT_NO_WAIVER | E20: =IF(C20=Assumptions!$D$4,"LIVE SELECTED","CAPTURED") -> CAPTURED | F20: 115.88908 | G20: 0.094841257 | H20: 513.52483 | I20: 467.10058 | J20: 250.9338 | K20: 210.96251 | L20: 0 | M20: 239.69285 | N20: 263.90228 | O20: 54.107146 | P20: 54.107146 | Q20: 6.8131589 | R20: 1.861981 | S20: 2026-04-30 | T20: 2026-10-31 | U20: 2026-11-30 | V20: 2027-02-28 | W20: 689.71319 | X20: 538.04051 | Y20: 41.947002 | Z20: 2026-09-11T17:39:57Z | AA20: 58e1b83a644021b785162d851e1539dd65dff9f5 | AB20: 126ef393472d5f74abd447b237b1319643c1effb36a37f052496b114af1a6fe1 | AC20: 1712129.8 | AD20: =Assumptions!$D$7 -> 1712129.8 | AE20: =IF(ABS(AC20-AD20)<=0.000001,"CURRENT","STALE") -> CURRENT

Sheet Historicals
C2: Quanex reported historical spread
C4: FY2021-FY2023 pre-Tyman; FY2024 includes approximately three months of Tyman; FY2025 is the first full post-Tyman year.
C6: Metric | D6: FY2021 | E6: FY2022 | F6: FY2023 | G6: FY2024 | H6: FY2025 | I6: Units | J6: Source IDs | K6: Status
C7: Income statement
C8: Revenue | D8: 1072.149 | E8: 1221.502 | F8: 1130.583 | G8: 1277.862 | H8: 1837.641 | I8: USD_millions | J8: SRC-014;SRC-001 | K8: supported
C9: Cost of sales before D&A | D9: -831.541 | E9: -953.004 | F9: -853.059 | G9: -972.238 | H9: -1338.413 | I9: USD_millions | J9: SRC-014;SRC-001 | K9: supported
C10: Gross profit | D10: 240.608 | E10: 268.498 | F10: 277.524 | G10: 305.624 | H10: 499.228 | I10: USD_millions | J10: SRC-014;SRC-001 | K10: supported
C11: SG&A | D11: -115.967 | E11: -117.108 | F11: -123.957 | G11: -190.47 | H11: -277.261 | I11: USD_millions | J11: SRC-014;SRC-001 | K11: supported
C12: D&A | D12: -42.732 | E12: -40.109 | F12: -42.866 | G12: -60.328 | H12: -103.444 | I12: USD_millions | J12: SRC-014;SRC-001 | K12: supported
C13: Goodwill impairment | D13: 0 | E13: 0 | F13: 0 | G13: 0 | H13: -302.284 | I13: USD_millions | J13: SRC-001 | K13: supported
C14: Operating income | D14: 81.87 | E14: 111.281 | F14: 110.701 | G14: 54.826 | H14: -193.952 | I14: USD_millions | J14: SRC-014;SRC-001 | K14: supported
C15: Interest expense | D15: -2.53 | E15: -2.559 | F15: -8.136 | G15: -20.593 | H15: -55.812 | I15: USD_millions | J15: SRC-014;SRC-001 | K15: supported
C16: Pretax income | D16: 80.094 | E16: 109.763 | F16: 97.046 | G16: 42.082 | H16: -242.593 | I16: USD_millions | J16: SRC-014;SRC-001 | K16: supported
C17: Income-tax expense | D17: -23.114 | E17: -21.427 | F17: -14.545 | G17: -9.023 | H17: -8.213 | I17: USD_millions | J17: SRC-014;SRC-001 | K17: supported
C18: Net income | D18: 56.98 | E18: 88.336 | F18: 82.501 | G18: 33.059 | H18: -250.806 | I18: USD_millions | J18: SRC-014;SRC-001 | K18: supported
C19: Cash flow
C20: Cash flow from operations | D20: 78.588 | E20: 97.965 | F20: 147.052 | G20: 88.812 | H20: 164.897 | I20: USD_millions | J20: SRC-014;SRC-001 | K20: supported
C21: Capital expenditures | D21: -24.008 | E21: -33.121 | F21: -37.39 | G21: -37.086 | H21: -62.642 | I21: USD_millions | J21: SRC-014;SRC-001 | K21: supported
C22: Free cash flow | D22: 54.58 | E22: 64.844 | F22: 109.662 | G22: 51.726 | H22: 102.255 | I22: USD_millions | J22: SRC-014;SRC-001 | K22: supported
C23: Acquisition cash flows | F23: -91.302 | G23: -398.554 | H23: 0 | I23: USD_millions | J23: SRC-001 | K23: supported
C24: Dividends paid | D24: -10.779 | E24: -10.598 | F24: -10.639 | G24: -11.972 | H24: -14.889 | I24: USD_millions | J24: SRC-014;SRC-001 | K24: supported
C25: Share repurchases | D25: -11.182 | E25: -6.6 | F25: -5.593 | G25: 0 | H25: -32.36 | I25: USD_millions | J25: SRC-014;SRC-001 | K25: supported
C26: Balance sheet
C27: Cash and cash equivalents | D27: 40.061 | E27: 55.093 | F27: 58.474 | G27: 97.744 | H27: 76.018 | I27: USD_millions | J27: SRC-014;SRC-012;SRC-001 | K27: supported
C28: Accounts receivable | D28: 108.309 | E28: 96.018 | F28: 97.311 | G28: 197.689 | H28: 205.384 | I28: USD_millions | J28: SRC-014;SRC-012;SRC-001 | K28: supported
C29: Inventory | D29: 92.529 | E29: 120.89 | F29: 97.959 | G29: 275.55 | H29: 254.122 | I29: USD_millions | J29: SRC-014;SRC-012;SRC-001 | K29: supported
C30: Accounts payable | D30: 86.765 | E30: 77.907 | F30: 74.371 | G30: 124.404 | H30: 131.307 | I30: USD_millions | J30: SRC-014;SRC-012;SRC-001 | K30: supported
C31: Current assets | D31: 249.047 | E31: 280.665 | F31: 273.6 | G31: 611.268 | H31: 573.775 | I31: USD_millions | J31: SRC-014;SRC-012;SRC-001 | K31: supported
C32: Current liabilities | D32: 158.001 | E32: 139.843 | F32: 134.663 | G32: 272.867 | H32: 281.545 | I32: USD_millions | J32: SRC-014;SRC-012;SRC-001 | K32: supported
C33: Total assets | D33: 717.323 | E33: 724.617 | F33: 831.143 | G33: 2319.788 | H33: 1968.233 | I33: USD_millions | J33: SRC-014;SRC-012;SRC-001 | K33: supported
C34: Total liabilities | D34: 297.541 | E34: 259.782 | F34: 285.589 | G34: 1309.042 | H34: 1242.054 | I34: USD_millions | J34: SRC-014;SRC-012;SRC-001 | K34: supported
C35: Shareholders' equity | D35: 419.782 | E35: 464.835 | F35: 545.554 | G35: 1010.746 | H35: 726.179 | I35: USD_millions | J35: SRC-014;SRC-012;SRC-001 | K35: supported
C36: Goodwill | D36: 149.205 | E36: 137.855 | F36: 182.956 | G36: 574.711 | H36: 271.346 | I36: USD_millions | J36: SRC-014;SRC-012;SRC-001 | K36: supported
C37: Intangible assets | D37: 82.41 | E37: 65.035 | F37: 74.115 | G37: 597.909 | H37: 549.137 | I37: USD_millions | J37: SRC-014;SRC-012;SRC-001 | K37: supported
C38: Debt
C39: Term-loan principal | D39: 0 | E39: 0 | F39: 0 | G39: 493.75 | H39: 468.75 | I39: USD_millions | J39: SRC-014;SRC-012;SRC-002 | K39: supported
C40: Revolver borrowings | D40: 38 | E40: 13 | F40: 15 | G40: 222.5 | H40: 172.5 | I40: USD_millions | J40: SRC-014;SRC-012;SRC-002 | K40: supported
C41: Total debt principal | D41: 53.537 | E41: 32.202 | F41: 70 | G41: 776.926 | H41: 703.869 | I41: USD_millions | J41: SRC-014;SRC-012;SRC-002 | K41: supported
C42: Total debt carrying amount | D42: 52.94 | E42: 30.674 | F42: 68.8 | G42: 762.943 | H42: 692.829 | I42: USD_millions | J42: SRC-014;SRC-012;SRC-001 | K42: supported
C43: Finance lease obligations | D43: 15.537 | E43: 19.202 | F43: 55 | G43: 60.676 | H43: 62.619 | I43: USD_millions | J43: SRC-014;SRC-012;SRC-002 | K43: supported
...

Sheet Credit Adjustments
C2: Earnings definitions and lender adjustments
S4: Earnings layer | T4: FY2024 | U4: FY2025
S5: Unadjusted EBITDA | T5: =D9 -> 115.154 | U5: =E9 -> -90.508
C6: Earnings layer | D6: FY2024 | E6: FY2025 | S6: Company-adjusted EBITDA | T6: =D11 -> 182.383 | U6: =E11 -> 242.89
C7: GAAP operating income | D7: 54.826 | E7: -193.952 | S7: Partial contractual | T7: =D12 -> 0 | U7: =E12 -> 229.642
C8: Add: D&A | D8: 60.328 | E8: 103.444 | S8: Lender-base EBITDA | T8: =D14 -> 179.358 | U8: =E14 -> 225.344
C9: Unadjusted EBITDA | D9: =SUM(D7:D8) -> 115.154 | E9: =SUM(E7:E8) -> -90.508
C10: Company adjustments | D10: =D11-D9 -> 67.229 | E10: =E11-E9 -> 333.398
C11: Company-adjusted EBITDA | D11: 182.383 | E11: 242.89
C12: Partial contractual reconstruction | E12: 229.642
C13: Owner-reviewed lender adjustments | D13: =SUMIFS($H$20:$H$30,$D$20:$D$30,D$6) -> 64.204 | E13: =SUMIFS($H$20:$H$30,$D$20:$D$30,E$6) -> 315.852
C14: Owner-reviewed lender-base EBITDA | D14: =D9+D13 -> 179.358 | E14: =E9+E13 -> 225.344
C16: Unofficial contractual reconstruction; AC-011 cash outflow retained; goodwill impairment remains a major adverse risk signal.
C19: Adjustment ID | D19: Period | E19: Description | F19: Reported | G19: Low | H19: Base | I19: High/company | J19: Cash status | K19: Recurrence | L19: Contractual status | M19: Owner review | N19: Lender rationale | O19: Source ID | P19: Limitation | Q19: Double count check
C20: AC-001 | D20: FY2025 | E20: Goodwill impairment | F20: 302.284 | G20: 302.284 | H20: 302.284 | I20: 302.284 | J20: noncash | K20: nonrecurring_charge_but_material_business_risk_signal | L20: likely_permitted_nonrecurring_noncash_or_intangible_write_down | M20: owner_reviewed | N20: Full mathematical reversal is appropriate because the charge is noncash; retain the impairment as a major asset-quality and forecasting warning. | O20: SRC-002 | P20: Official compliance certificate and lender calculation are unavailable. | Q20: Matches the FY2025 GAAP impairment and CFO noncash addback; do not add either again.
C21: AC-002 | D21: FY2025 | E21: Plant relocation cost recorded in cost of sales | F21: 1.432 | G21: 0 | H21: 0 | I21: 1.432 | J21: cash_status_not_disclosed | K21: temporary_but_execution_cost_may_recur_during_stabilization | L21: not_clearly_permitted_from_public_record | M21: owner_reviewed | N21: Owner-reviewed base acceptance is zero because the disclosure does not establish cash character, completion, or nonrecurrence; the full amount remains only in the company/high sensitivity. | O21: SRC-002 | P21: Invoice detail, cash timing, completion evidence, and contractual classification. | Q21: Paired with AC-003; neither may also be included through a broader restructuring line.
C22: AC-003 | D22: FY2025 | E22: Plant relocation cost recorded in SG&A | F22: 0.221 | G22: 0 | H22: 0 | I22: 0.221 | J22: cash_status_not_disclosed | K22: temporary_but_execution_cost_may_recur_during_stabilization | L22: not_clearly_permitted_from_public_record | M22: owner_reviewed | N22: Owner-reviewed base acceptance is zero because the disclosure does not establish cash character, completion, or nonrecurrence; the full amount remains only in the company/high sensitivity. | O22: SRC-002 | P22: Invoice detail, cash timing, completion evidence, and contractual classification. | Q22: Paired with AC-002; neither may also be included through a broader restructuring line.
C23: AC-004 | D23: FY2025 | E23: Inventory purchase-accounting step-up | F23: 9.007 | G23: 9.007 | H23: 9.007 | I23: 9.007 | J23: noncash_purchase_accounting_expense | K23: nonrecurring_for_acquired_inventory | L23: likely_permitted_nonrecurring_noncash_acquisition_accounting_subject_to_certificate | M23: owner_reviewed | N23: The fair-value step-up is a finite acquisition-accounting charge rather than recurring operating cost; full acceptance does not erase acquisition risk. | O23: SRC-002 | P23: Official contractual classification and compliance certificate. | Q23: Do not also add this amount through a pro forma purchase-accounting adjustment.
C24: AC-005 | D24: FY2025 | E24: Transaction, advisory, reorganization, and product-recall composite | F24: 10.263 | G24: 0 | H24: 0 | I24: 10.263 | J24: mixed_or_not_disclosed | K24: mixed_category_includes_potentially_recurring_operational_cost | L24: mixed_and_not_determinable_from_public_record | M24: owner_reviewed | N24: Base acceptance is zero because transaction, reorganization, and recall costs are inseparable; the full company amount is retained only as an upper case pending evidence. | O24: SRC-002 | P24: Component amounts, invoices, cash/noncash split, dates, recall scope, and recurrence evidence. | Q24: Potential overlap with acquisition costs, restructuring, and operating remediation; no other bridge may absorb it.
C25: AC-006 | D25: FY2025 | E25: Restructuring, severance, and software | F25: 10.191 | G25: 4.561 | H25: 4.561 | I25: 10.191 | J25: mixed_4.561_noncash_remainder_not_established_noncash | K25: partly_nonrecurring_with_cash_execution_risk | L25: only_identified_one_time_noncash_restructuring_component_clearly_permitted | M25: owner_reviewed | N25: Accept only the $4.561 million noncash restructuring amount reconciled in the cash-flow statement; defer the remaining $5.630 million. | O25: SRC-002 | P25: Cash payments, project completion, software write-off detail, and official covenant treatment. | Q25: The $4.561 million CFO addback is evidence of noncash character, not a second EBITDA adjustment.
C26: AC-007 | D26: FY2025 | E26: Tyman post-measurement-period deferred-tax correction | F26: 9 | G26: 0 | H26: 0 | I26: 0 | J26: noncash_deferred_tax_accounting | K26: nonrecurring_tax_measurement_correction | L26: tax_is_already_excluded_in_ebitda | M26: owner_reviewed | N26: The $9 million charge matters to adjusted net income and tax quality but cannot be added again to EBITDA because income taxes are already excluded. | O26: SRC-001 | P26: Cash-tax implications, if any, remain unavailable. | Q26: Adding it to EBITDA would double count the standard tax addback.
C27: AC-008 | D27: FY2024 | E27: Plant closure cost recorded in cost of sales | F27: 3.025 | G27: 0 | H27: 0 | I27: 3.025 | J27: cash_status_not_disclosed | K27: closure_related_but_recurrence_and_cash_timing_not_proven | L27: not_clearly_permitted_from_public_record | M27: owner_reviewed | N27: Owner-reviewed base acceptance is zero because closure specificity alone does not prove cash character, completion, or nonrecurrence; the full amount remains only in the company/high sensitivity. | O27: SRC-002 | P27: Cash/noncash split, closure completion, and contractual classification. | Q27: Must not overlap with other restructuring or disposition adjustments.
C28: AC-009 | D28: FY2024 | E28: Plant closure gain recorded in SG&A | F28: -4.196 | G28: -4.196 | H28: -4.196 | I28: -4.196 | J28: noncash_gain_component_with_separate_sale_proceeds | K28: nonrecurring_gain | L28: likely_required_deduction_for_unusual_or_disposition_gain | M28: owner_reviewed | N28: Deduct the gain in full, consistent with both the company bridge and lender conservatism; excluding losses while retaining gains would be asymmetric. | O28: SRC-002 | P28: Official compliance presentation is unavailable. | Q28: Do not also deduct the related disposition gain through another contractual line.
C29: AC-010 | D29: FY2024 | E29: Inventory and receivables purchase-accounting step-up | F29: 29.076 | G29: 29.076 | H29: 29.076 | I29: 29.076 | J29: noncash_purchase_accounting_expense | K29: nonrecurring_for_acquired_balances | L29: likely_permitted_acquisition_accounting_or_pro_forma_item_subject_to_certificate | M29: owner_reviewed | N29: Owner-reviewed full acceptance reflects a finite acquisition-accounting effect; collectability, cash-realization, integration, and pro forma limitations remain separate from the earnings normalization. | O29: SRC-002 | P29: Official contractual bridge, precise inventory/receivable split, and evidence on collectability and cash realization. | Q29: Do not also include it in a separate acquisition pro forma or working-capital adjustment.
C30: AC-011 | D30: FY2024 | E30: Tyman transaction and advisory fees | F30: 39.324 | G30: 39.324 | H30: 39.324 | I30: 39.324 | J30: cash | K30: nonrecurring_completed_acquisition_cost | L30: not_determinable_without_out_of_pocket_support_incurrence_dates_and_compliance_certificate | M30: owner_reviewed | N30: Owner-reviewed lender earnings normalization accepts the completed-transaction cost, but contractual eligibility remains unresolved and historical cash conversion continues to reflect the cash use. | O30: SRC-002 | P30: Invoices, payees, exact incurrence dates, and official compliance certificate. | Q30: Do not also add the same fees through a pro forma acquisition-cost line.

Sheet Transaction
C2: Transaction and financing alternatives
C4: Case selected: | D4: =Assumptions!$D$4 -> Base
C6: Selected refinancing sources and uses
C7: Source | D7: USD millions | F7: Use / control
C8: Term funding | D8: =Assumptions!D12 -> 635 | F8: Existing debt payoff and approved closing uses | G8: 679.89772
C9: Opening revolver | D9: =Assumptions!D15 -> 29.897719 | F9: Reference closing uses | G9: 679.89772
C10: Conditional non-debt source | D10: =Assumptions!D13 -> 15 | F10: Sources less uses | G10: =D11-G9 -> 0
C11: Total sources | D11: =SUM(D8:D10) -> 679.89772 | F11: Conditional source status | G11: Pending information / condition precedent
D12: =G10 -> 0 | F12: Sources and uses check | G12: =IF(ABS(G10)<=0.001,"PASS","FAIL") -> PASS
C14: Opening capitalization
C15: Opening bank debt | D15: =Assumptions!D12+Assumptions!D15 -> 664.89772
C16: Retained other funded debt | D16: =Assumptions!D17 -> 62.619
C17: Opening total funded debt | D17: =SUM(D15:D16) -> 727.51672
C18: Opening gross funded leverage | D18: =D17/'Credit Adjustments'!E14 -> 3.2284717
C20: Existing and refinancing comparison
C21: Alternative | D21: Opening funded debt | E21: Common-horizon ending debt | F21: Unsupported maturity gap | G21: All-in base liquidity
C22: Retain existing facilities | D22: 703.869 | E22: 495.36828 | F22: 432.74928 | G22: 261.40228
C23: Selected $635m refinancing | D23: =D17 -> 727.51672 | E23: 514.75371 | F23: 324.77971 | G23: 263.90228
C24: $650m reference refinancing | D24: 742.51672 | E24: 507.95366 | F24: 340.94783 | G24: 253.84583
C26: Limited amendment / extension | D26: N/D | E26: N/D | F26: N/D | G26: Public information is insufficient for quantitative modeling.
C28: Commitment and unresolved closing items
C29: Revolver commitment | D29: =Assumptions!D14 -> 300 | F29: Financing fees not already approved | G29: N/D
C30: Letters of credit | D30: =Assumptions!D16 -> 6.2 | F30: LC transition mechanics | G30: Pending information
C31: Gross availability | D31: =Assumptions!D14-Assumptions!D15 -> 270.10228 | F31: Final lender pricing | G31: Pending information
C32: Usable availability after LCs | D32: =Assumptions!D14-Assumptions!D16-Assumptions!D15 -> 263.90228 | F32: Final payoff and funds flow | G32: Pending information

Sheet Forecast
C2: Quarterly operating and cash forecast
C4: Case selected: | D4: =Assumptions!$D$4 -> Base
C7: Metric | D7: Q2:26 | E7: Q3:26 | F7: Q4:26 | G7: Q1:27 | H7: Q2:27 | I7: Q3:27 | J7: Q4:27 | K7: Q1:28 | L7: Q2:28 | M7: Q3:28 | N7: Q4:28 | O7: Q1:29 | P7: Q2:29 | Q7: Q3:29 | R7: Q4:29 | S7: Q1:30 | T7: Q2:30 | U7: Q3:30 | V7: Q4:30 | W7: Q1:31
D8: 46142 | E8: 46234 | F8: 46326 | G8: 46418 | H8: 46507 | I8: 46599 | J8: 46691 | K8: 46783 | L8: 46873 | M8: 46965 | N8: 47057 | O8: 47149 | P8: 47238 | Q8: 47330 | R8: 47422 | S8: 47514 | T8: 47603 | U8: 47695 | V8: 47787 | W8: 47879
C10: Revenue | D10: =SUMIFS(Assumptions!$L$41:$L$364,Assumptions!$C$41:$C$364,$D$4,Assumptions!$I$41:$I$364,"FY2026",Assumptions!$J$41:$J$364,"Q2") -> 452.46669 | E10: =SUMIFS(Assumptions!$L$41:$L$364,Assumptions!$C$41:$C$364,$D$4,Assumptions!$I$41:$I$364,"FY2026",Assumptions!$J$41:$J$364,"Q3") -> 495.26062 | F10: =SUMIFS(Assumptions!$L$41:$L$364,Assumptions!$C$41:$C$364,$D$4,Assumptions!$I$41:$I$364,"FY2026",Assumptions!$J$41:$J$364,"Q4") -> 489.83375 | G10: =SUMIFS(Assumptions!$L$41:$L$364,Assumptions!$C$41:$C$364,$D$4,Assumptions!$I$41:$I$364,"FY2027",Assumptions!$J$41:$J$364,"Q1") -> 400.024 | H10: =SUMIFS(Assumptions!$L$41:$L$364,Assumptions!$C$41:$C$364,$D$4,Assumptions!$I$41:$I$364,"FY2027",Assumptions!$J$41:$J$364,"Q2") -> 452.45538 | I10: =SUMIFS(Assumptions!$L$41:$L$364,Assumptions!$C$41:$C$364,$D$4,Assumptions!$I$41:$I$364,"FY2027",Assumptions!$J$41:$J$364,"Q3") -> 495.24824 | J10: =SUMIFS(Assumptions!$L$41:$L$364,Assumptions!$C$41:$C$364,$D$4,Assumptions!$I$41:$I$364,"FY2027",Assumptions!$J$41:$J$364,"Q4") -> 489.82151 | K10: =SUMIFS(Assumptions!$L$41:$L$364,Assumptions!$C$41:$C$364,$D$4,Assumptions!$I$41:$I$364,"FY2028",Assumptions!$J$41:$J$364,"Q1") -> 400.014 | L10: =SUMIFS(Assumptions!$L$41:$L$364,Assumptions!$C$41:$C$364,$D$4,Assumptions!$I$41:$I$364,"FY2028",Assumptions!$J$41:$J$364,"Q2") -> 452.44406 | M10: =SUMIFS(Assumptions!$L$41:$L$364,Assumptions!$C$41:$C$364,$D$4,Assumptions!$I$41:$I$364,"FY2028",Assumptions!$J$41:$J$364,"Q3") -> 495.23586 | N10: =SUMIFS(Assumptions!$L$41:$L$364,Assumptions!$C$41:$C$364,$D$4,Assumptions!$I$41:$I$364,"FY2028",Assumptions!$J$41:$J$364,"Q4") -> 489.80926 | O10: =SUMIFS(Assumptions!$L$41:$L$364,Assumptions!$C$41:$C$364,$D$4,Assumptions!$I$41:$I$364,"FY2029",Assumptions!$J$41:$J$364,"Q1") -> 400.004 | P10: =SUMIFS(Assumptions!$L$41:$L$364,Assumptions!$C$41:$C$364,$D$4,Assumptions!$I$41:$I$364,"FY2029",Assumptions!$J$41:$J$364,"Q2") -> 452.43275 | Q10: =SUMIFS(Assumptions!$L$41:$L$364,Assumptions!$C$41:$C$364,$D$4,Assumptions!$I$41:$I$364,"FY2029",Assumptions!$J$41:$J$364,"Q3") -> 495.22347 | R10: =SUMIFS(Assumptions!$L$41:$L$364,Assumptions!$C$41:$C$364,$D$4,Assumptions!$I$41:$I$364,"FY2029",Assumptions!$J$41:$J$364,"Q4") -> 489.79702 | S10: =SUMIFS(Assumptions!$L$41:$L$364,Assumptions!$C$41:$C$364,$D$4,Assumptions!$I$41:$I$364,"FY2030",Assumptions!$J$41:$J$364,"Q1") -> 399.994 | T10: =SUMIFS(Assumptions!$L$41:$L$364,Assumptions!$C$41:$C$364,$D$4,Assumptions!$I$41:$I$364,"FY2030",Assumptions!$J$41:$J$364,"Q2") -> 452.42144 | U10: =SUMIFS(Assumptions!$L$41:$L$364,Assumptions!$C$41:$C$364,$D$4,Assumptions!$I$41:$I$364,"FY2030",Assumptions!$J$41:$J$364,"Q3") -> 495.21109 | V10: =SUMIFS(Assumptions!$L$41:$L$364,Assumptions!$C$41:$C$364,$D$4,Assumptions!$I$41:$I$364,"FY2030",Assumptions!$J$41:$J$364,"Q4") -> 489.78477 | W10: =SUMIFS(Assumptions!$L$41:$L$364,Assumptions!$C$41:$C$364,$D$4,Assumptions!$I$41:$I$364,"FY2031",Assumptions!$J$41:$J$364,"Q1") -> 399.984
C11: Gross margin | D11: =AVERAGEIFS(Assumptions!$M$41:$M$364,Assumptions!$C$41:$C$364,$D$4,Assumptions!$I$41:$I$364,"FY2026",Assumptions!$J$41:$J$364,"Q2")/100 -> 0.28869322 | E11: =AVERAGEIFS(Assumptions!$M$41:$M$364,Assumptions!$C$41:$C$364,$D$4,Assumptions!$I$41:$I$364,"FY2026",Assumptions!$J$41:$J$364,"Q3")/100 -> 0.27690174 | F11: =AVERAGEIFS(Assumptions!$M$41:$M$364,Assumptions!$C$41:$C$364,$D$4,Assumptions!$I$41:$I$364,"FY2026",Assumptions!$J$41:$J$364,"Q4")/100 -> 0.27915917 | G11: =AVERAGEIFS(Assumptions!$M$41:$M$364,Assumptions!$C$41:$C$364,$D$4,Assumptions!$I$41:$I$364,"FY2027",Assumptions!$J$41:$J$364,"Q1")/100 -> 0.22909675 | H11: =AVERAGEIFS(Assumptions!$M$41:$M$364,Assumptions!$C$41:$C$364,$D$4,Assumptions!$I$41:$I$364,"FY2027",Assumptions!$J$41:$J$364,"Q2")/100 -> 0.28869322 | I11: =AVERAGEIFS(Assumptions!$M$41:$M$364,Assumptions!$C$41:$C$364,$D$4,Assumptions!$I$41:$I$364,"FY2027",Assumptions!$J$41:$J$364,"Q3")/100 -> 0.27690174 | J11: =AVERAGEIFS(Assumptions!$M$41:$M$364,Assumptions!$C$41:$C$364,$D$4,Assumptions!$I$41:$I$364,"FY2027",Assumptions!$J$41:$J$364,"Q4")/100 -> 0.27915917 | K11: =AVERAGEIFS(Assumptions!$M$41:$M$364,Assumptions!$C$41:$C$364,$D$4,Assumptions!$I$41:$I$364,"FY2028",Assumptions!$J$41:$J$364,"Q1")/100 -> 0.22909675 | L11: =AVERAGEIFS(Assumptions!$M$41:$M$364,Assumptions!$C$41:$C$364,$D$4,Assumptions!$I$41:$I$364,"FY2028",Assumptions!$J$41:$J$364,"Q2")/100 -> 0.28869322 | M11: =AVERAGEIFS(Assumptions!$M$41:$M$364,Assumptions!$C$41:$C$364,$D$4,Assumptions!$I$41:$I$364,"FY2028",Assumptions!$J$41:$J$364,"Q3")/100 -> 0.27690174 | N11: =AVERAGEIFS(Assumptions!$M$41:$M$364,Assumptions!$C$41:$C$364,$D$4,Assumptions!$I$41:$I$364,"FY2028",Assumptions!$J$41:$J$364,"Q4")/100 -> 0.27915917 | O11: =AVERAGEIFS(Assumptions!$M$41:$M$364,Assumptions!$C$41:$C$364,$D$4,Assumptions!$I$41:$I$364,"FY2029",Assumptions!$J$41:$J$364,"Q1")/100 -> 0.22909675 | P11: =AVERAGEIFS(Assumptions!$M$41:$M$364,Assumptions!$C$41:$C$364,$D$4,Assumptions!$I$41:$I$364,"FY2029",Assumptions!$J$41:$J$364,"Q2")/100 -> 0.28869322 | Q11: =AVERAGEIFS(Assumptions!$M$41:$M$364,Assumptions!$C$41:$C$364,$D$4,Assumptions!$I$41:$I$364,"FY2029",Assumptions!$J$41:$J$364,"Q3")/100 -> 0.27690174 | R11: =AVERAGEIFS(Assumptions!$M$41:$M$364,Assumptions!$C$41:$C$364,$D$4,Assumptions!$I$41:$I$364,"FY2029",Assumptions!$J$41:$J$364,"Q4")/100 -> 0.27915917 | S11: =AVERAGEIFS(Assumptions!$M$41:$M$364,Assumptions!$C$41:$C$364,$D$4,Assumptions!$I$41:$I$364,"FY2030",Assumptions!$J$41:$J$364,"Q1")/100 -> 0.22909675 | T11: =AVERAGEIFS(Assumptions!$M$41:$M$364,Assumptions!$C$41:$C$364,$D$4,Assumptions!$I$41:$I$364,"FY2030",Assumptions!$J$41:$J$364,"Q2")/100 -> 0.28869322 | U11: =AVERAGEIFS(Assumptions!$M$41:$M$364,Assumptions!$C$41:$C$364,$D$4,Assumptions!$I$41:$I$364,"FY2030",Assumptions!$J$41:$J$364,"Q3")/100 -> 0.27690174 | V11: =AVERAGEIFS(Assumptions!$M$41:$M$364,Assumptions!$C$41:$C$364,$D$4,Assumptions!$I$41:$I$364,"FY2030",Assumptions!$J$41:$J$364,"Q4")/100 -> 0.27915917 | W11: =AVERAGEIFS(Assumptions!$M$41:$M$364,Assumptions!$C$41:$C$364,$D$4,Assumptions!$I$41:$I$364,"FY2031",Assumptions!$J$41:$J$364,"Q1")/100 -> 0.22909675
C12: Gross profit | D12: =D10*D11 -> 130.62406 | E12: =E10*E11 -> 137.13852 | F12: =F10*F11 -> 136.74159 | G12: =G10*G11 -> 91.6442 | H12: =H10*H11 -> 130.6208 | I12: =I10*I11 -> 137.1351 | J12: =J10*J11 -> 136.73817 | K12: =K10*K11 -> 91.641909 | ... W12: =W10*W11 -> 91.635036
C13: Cash operating expenses | D13: =D12-D14 -> 67.436088 | E13: =E12-E14 -> 73.814138 | F13: =F12-F14 -> 73.005313 | G13: =G12-G14 -> 59.619977 | H13: =H12-H14 -> 67.434402 | I13: =I12-I14 -> 73.812292 | J13: =J12-J14 -> 73.003487 | K13: =K12-K14 -> 59.618486 | ... W13: =W12-W14 -> 59.614015
C14: Lender-base EBITDA | D14: =SUMIFS(Assumptions!$N$41:$N$364,Assumptions!$C$41:$C$364,$D$4,Assumptions!$I$41:$I$364,"FY2026",Assumptions!$J$41:$J$364,"Q2")*(1+Assumptions!$D$21) -> 63.187976 | E14: =SUMIFS(Assumptions!$N$41:$N$364,Assumptions!$C$41:$C$364,$D$4,Assumptions!$I$41:$I$364,"FY2026",Assumptions!$J$41:$J$364,"Q3")*(1+Assumptions!$D$21) -> 63.324387 | F14: =SUMIFS(Assumptions!$N$41:$N$364,Assumptions!$C$41:$C$364,$D$4,Assumptions!$I$41:$I$364,"FY2026",Assumptions!$J$41:$J$364,"Q4")*(1+Assumptions!$D$21) -> 63.736274 | G14: =SUMIFS(Assumptions!$N$41:$N$364,Assumptions!$C$41:$C$364,$D$4,Assumptions!$I$41:$I$364,"FY2027",Assumptions!$J$41:$J$364,"Q1")*(1+Assumptions!$D$21) -> 32.024223 | H14: =SUMIFS(Assumptions!$N$41:$N$364,Assumptions!$C$41:$C$364,$D$4,Assumptions!$I$41:$I$364,"FY2027",Assumptions!$J$41:$J$364,"Q2")*(1+Assumptions!$D$21) -> 63.186396 | I14: =SUMIFS(Assumptions!$N$41:$N$364,Assumptions!$C$41:$C$364,$D$4,Assumptions!$I$41:$I$364,"FY2027",Assumptions!$J$41:$J$364,"Q3")*(1+Assumptions!$D$21) -> 63.322804 | J14: =SUMIFS(Assumptions!$N$41:$N$364,Assumptions!$C$41:$C$364,$D$4,Assumptions!$I$41:$I$364,"FY2027",Assumptions!$J$41:$J$364,"Q4")*(1+Assumptions!$D$21) -> 63.73468 | K14: =SUMIFS(Assumptions!$N$41:$N$364,Assumptions!$C$41:$C$364,$D$4,Assumptions!$I$41:$I$364,"FY2028",Assumptions!$J$41:$J$364,"Q1")*(1+Assumptions!$D$21) -> 32.023422 | L14: =SUMIFS(Assumptions!$N$41:$N$364,Assumptions!$C$41:$C$364,$D$4,Assumptions!$I$41:$I$364,"FY2028",Assumptions!$J$41:$J$364,"Q2")*(1+Assumptions!$D$21) -> 63.184817 | M14: =SUMIFS(Assumptions!$N$41:$N$364,Assumptions!$C$41:$C$364,$D$4,Assumptions!$I$41:$I$364,"FY2028",Assumptions!$J$41:$J$364,"Q3")*(1+Assumptions!$D$21) -> 63.321221 | N14: =SUMIFS(Assumptions!$N$41:$N$364,Assumptions!$C$41:$C$364,$D$4,Assumptions!$I$41:$I$364,"FY2028",Assumptions!$J$41:$J$364,"Q4")*(1+Assumptions!$D$21) -> 63.733087 | O14: =SUMIFS(Assumptions!$N$41:$N$364,Assumptions!$C$41:$C$364,$D$4,Assumptions!$I$41:$I$364,"FY2029",Assumptions!$J$41:$J$364,"Q1")*(1+Assumptions!$D$21) -> 32.022622 | P14: =SUMIFS(Assumptions!$N$41:$N$364,Assumptions!$C$41:$C$364,$D$4,Assumptions!$I$41:$I$364,"FY2029",Assumptions!$J$41:$J$364,"Q2")*(1+Assumptions!$D$21) -> 63.183237 | Q14: =SUMIFS(Assumptions!$N$41:$N$364,Assumptions!$C$41:$C$364,$D$4,Assumptions!$I$41:$I$364,"FY2029",Assumptions!$J$41:$J$364,"Q3")*(1+Assumptions!$D$21) -> 63.319638 | R14: =SUMIFS(Assumptions!$N$41:$N$364,Assumptions!$C$41:$C$364,$D$4,Assumptions!$I$41:$I$364,"FY2029",Assumptions!$J$41:$J$364,"Q4")*(1+Assumptions!$D$21) -> 63.731494 | S14: =SUMIFS(Assumptions!$N$41:$N$364,Assumptions!$C$41:$C$364,$D$4,Assumptions!$I$41:$I$364,"FY2030",Assumptions!$J$41:$J$364,"Q1")*(1+Assumptions!$D$21) -> 32.021821 | T14: =SUMIFS(Assumptions!$N$41:$N$364,Assumptions!$C$41:$C$364,$D$4,Assumptions!$I$41:$I$364,"FY2030",Assumptions!$J$41:$J$364,"Q2")*(1+Assumptions!$D$21) -> 63.181658 | U14: =SUMIFS(Assumptions!$N$41:$N$364,Assumptions!$C$41:$C$364,$D$4,Assumptions!$I$41:$I$364,"FY2030",Assumptions!$J$41:$J$364,"Q3")*(1+Assumptions!$D$21) -> 63.318055 | V14: =SUMIFS(Assumptions!$N$41:$N$364,Assumptions!$C$41:$C$364,$D$4,Assumptions!$I$41:$I$364,"FY2030",Assumptions!$J$41:$J$364,"Q4")*(1+Assumptions!$D$21) -> 63.7299 | W14: =SUMIFS(Assumptions!$N$41:$N$364,Assumptions!$C$41:$C$364,$D$4,Assumptions!$I$41:$I$364,"FY2031",Assumptions!$J$41:$J$364,"Q1")*(1+Assumptions!$D$21) -> 32.021021
C15: EBITDA margin | D15: =IF(D10=0,"",D14/D10) -> 0.13965222 | E15: =IF(E10=0,"",E14/E10) -> 0.12786074 | F15: =IF(F10=0,"",F14/F10) -> 0.13011817 | G15: =IF(G10=0,"",G14/G10) -> 0.080055755 | H15: =IF(H10=0,"",H14/H10) -> 0.13965222 | I15: =IF(I10=0,"",I14/I10) -> 0.12786074 | J15: =IF(J10=0,"",J14/J10) -> 0.13011817 | K15: =IF(K10=0,"",K14/K10) -> 0.080055755 | ... W15: =IF(W10=0,"",W14/W10) -> 0.080055755
C16: Depreciation and amortization | D16: =SUMIFS(Assumptions!$O$41:$O$364,Assumptions!$C$41:$C$364,$D$4,Assumptions!$I$41:$I$364,"FY2026",Assumptions!$J$41:$J$364,"Q2") -> -25.470255 | E16: =SUMIFS(Assumptions!$O$41:$O$364,Assumptions!$C$41:$C$364,$D$4,Assumptions!$I$41:$I$364,"FY2026",Assumptions!$J$41:$J$364,"Q3") -> -27.879211 | F16: =SUMIFS(Assumptions!$O$41:$O$364,Assumptions!$C$41:$C$364,$D$4,Assumptions!$I$41:$I$364,"FY2026",Assumptions!$J$41:$J$364,"Q4") -> -27.573722 | G16: =SUMIFS(Assumptions!$O$41:$O$364,Assumptions!$C$41:$C$364,$D$4,Assumptions!$I$41:$I$364,"FY2027",Assumptions!$J$41:$J$364,"Q1") -> -22.518151 | H16: =SUMIFS(Assumptions!$O$41:$O$364,Assumptions!$C$41:$C$364,$D$4,Assumptions!$I$41:$I$364,"FY2027",Assumptions!$J$41:$J$364,"Q2") -> -25.469618 | I16: =SUMIFS(Assumptions!$O$41:$O$364,Assumptions!$C$41:$C$364,$D$4,Assumptions!$I$41:$I$364,"FY2027",Assumptions!$J$41:$J$364,"Q3") -> -27.878514 | J16: =SUMIFS(Assumptions!$O$41:$O$364,Assumptions!$C$41:$C$364,$D$4,Assumptions!$I$41:$I$364,"FY2027",Assumptions!$J$41:$J$364,"Q4") -> -27.573032 | K16: =SUMIFS(Assumptions!$O$41:$O$364,Assumptions!$C$41:$C$364,$D$4,Assumptions!$I$41:$I$364,"FY2028",Assumptions!$J$41:$J$364,"Q1") -> -22.517588 | L16: =SUMIFS(Assumptions!$O$41:$O$364,Assumptions!$C$41:$C$364,$D$4,Assumptions!$I$41:$I$364,"FY2028",Assumptions!$J$41:$J$364,"Q2") -> -25.468981 | M16: =SUMIFS(Assumptions!$O$41:$O$364,Assumptions!$C$41:$C$364,$D$4,Assumptions!$I$41:$I$364,"FY2028",Assumptions!$J$41:$J$364,"Q3") -> -27.877817 | N16: =SUMIFS(Assumptions!$O$41:$O$364,Assumptions!$C$41:$C$364,$D$4,Assumptions!$I$41:$I$364,"FY2028",Assumptions!$J$41:$J$364,"Q4") -> -27.572343 | O16: =SUMIFS(Assumptions!$O$41:$O$364,Assumptions!$C$41:$C$364,$D$4,Assumptions!$I$41:$I$364,"FY2029",Assumptions!$J$41:$J$364,"Q1") -> -22.517025 | P16: =SUMIFS(Assumptions!$O$41:$O$364,Assumptions!$C$41:$C$364,$D$4,Assumptions!$I$41:$I$364,"FY2029",Assumptions!$J$41:$J$364,"Q2") -> -25.468345 | Q16: =SUMIFS(Assumptions!$O$41:$O$364,Assumptions!$C$41:$C$364,$D$4,Assumptions!$I$41:$I$364,"FY2029",Assumptions!$J$41:$J$364,"Q3") -> -27.87712 | R16: =SUMIFS(Assumptions!$O$41:$O$364,Assumptions!$C$41:$C$364,$D$4,Assumptions!$I$41:$I$364,"FY2029",Assumptions!$J$41:$J$364,"Q4") -> -27.571654 | S16: =SUMIFS(Assumptions!$O$41:$O$364,Assumptions!$C$41:$C$364,$D$4,Assumptions!$I$41:$I$364,"FY2030",Assumptions!$J$41:$J$364,"Q1") -> -22.516462 | T16: =SUMIFS(Assumptions!$O$41:$O$364,Assumptions!$C$41:$C$364,$D$4,Assumptions!$I$41:$I$364,"FY2030",Assumptions!$J$41:$J$364,"Q2") -> -25.467708 | U16: =SUMIFS(Assumptions!$O$41:$O$364,Assumptions!$C$41:$C$364,$D$4,Assumptions!$I$41:$I$364,"FY2030",Assumptions!$J$41:$J$364,"Q3") -> -27.876423 | V16: =SUMIFS(Assumptions!$O$41:$O$364,Assumptions!$C$41:$C$364,$D$4,Assumptions!$I$41:$I$364,"FY2030",Assumptions!$J$41:$J$364,"Q4") -> -27.570964 | W16: =SUMIFS(Assumptions!$O$41:$O$364,Assumptions!$C$41:$C$364,$D$4,Assumptions!$I$41:$I$364,"FY2031",Assumptions!$J$41:$J$364,"Q1") -> -22.515899
C17: Operating profit | D17: =D14+D16 -> 37.717721 | E17: =E14+E16 -> 35.445176 | F17: =F14+F16 -> 36.162552 | G17: =G14+G16 -> 9.5060722 | H17: =H14+H16 -> 37.716778 | I17: =I14+I16 -> 35.44429 | J17: =J14+J16 -> 36.161648 | K17: =K14+K16 -> 9.5058345 | ... W17: =W14+W16 -> 9.5051216
